<?xml version="1.0" ?>
<sdf version="1.8">
    <model name='diff_drive'>

      <link name='base_link'>
      </link>
      <joint name='base_joint' type='fixed'>
        <parent>base_link</parent>
        <child>chassis</child>
      </joint>

      <link name='chassis'>
        <pose>0 0 0.15 0 0 0</pose>
        <inertial>
          <mass>1</mass>
          <inertia>
            <ixx>0.009375</ixx>
            <ixy>0</ixy>
            <ixz>0</ixz>
            <iyy>0.015</iyy>
            <iyz>0</iyz>
            <izz>0.009375</izz>
          </inertia>
        </inertial>
        <visual name='visual_chassis'>
          <geometry>
            <box>
              <size>0.3 0.3 0.15</size>
            </box>
          </geometry>
          <material>
            <ambient>0.5 0.5 1.0 1</ambient>
            <diffuse>0.5 0.5 1.0 1</diffuse>
            <specular>0.0 0.0 1.0 1</specular>
          </material>
        </visual>
        <collision name='collision_chassis'>
          <geometry>
            <box>
              <size>0.3 0.3 0.15</size>
            </box>
          </geometry>
        </collision>
      </link>

      <link name='left_wheel'>
        <pose>0.15 0.15 0.10 -1.5707 0 0</pose>
        <inertial>
          <mass>0.3</mass>
          <inertia>
              <ixx>0.0012</ixx>
              <ixy>0</ixy>
              <ixz>0</ixz>
              <iyy>0.0012</iyy>
              <iyz>0</iyz>
              <izz>0.0012</izz>
          </inertia>
        </inertial>
        <visual name='visual_left_wheel'>
          <geometry>
            <cylinder>
              <radius>0.05</radius>
              <length>0.03</length>
            </cylinder>
          </geometry>
          <material>
            <ambient>0.2 0.2 0.2 1</ambient>
            <diffuse>0.2 0.2 0.2 1</diffuse>
            <specular>0.2 0.2 0.2 1</specular>
          </material>
        </visual>
        <collision name='collision_left_wheel'>
          <geometry>
            <cylinder>
              <radius>0.05</radius>
              <length>0.03</length>
            </cylinder>
          </geometry>
        </collision>
      </link>

      <link name='right_wheel'>
        <pose>0.15 -0.15 0.10 -1.5707 0 0</pose>
        <inertial>
          <mass>0.3</mass>
          <inertia>
              <ixx>0.0012</ixx>
              <ixy>0</ixy>
              <ixz>0</ixz>
              <iyy>0.0012</iyy>
              <iyz>0</iyz>
              <izz>0.0012</izz>
          </inertia>
        </inertial>
        <visual name='visual_right_wheel'>
          <geometry>
            <cylinder>
              <radius>0.05</radius>
              <length>0.03</length>
            </cylinder>
          </geometry>
          <material>
            <ambient>0.2 0.2 0.2 1</ambient>
            <diffuse>0.2 0.2 0.2 1</diffuse>
            <specular>0.2 0.2 0.2 1</specular>
          </material>
        </visual>
        <collision name='collision_right_wheel'>
          <geometry>
            <cylinder>
              <radius>0.05</radius>
              <length>0.03</length>
            </cylinder>
          </geometry>
        </collision>
      </link>

      <link name='caster'>
        <pose>-0.15 0 0.10 0 0 0</pose>
        <inertial>
          <mass>0.1</mass>
          <inertia>
            <ixx>0.0001</ixx>
            <ixy>0</ixy>
            <ixz>0</ixz>
            <iyy>0.0001</iyy>
            <iyz>0</iyz>
            <izz>0.0001</izz>
          </inertia>
        </inertial>
        <visual name='visual_caster'>
          <geometry>
            <sphere>
              <radius>0.05</radius>
            </sphere>
          </geometry>
          <material>
            <ambient>0.2 0.2 0.2 1</ambient>
            <diffuse>0.2 0.2 0.2 1</diffuse>
            <specular>0.2 0.2 0.2 1</specular>
          </material>
        </visual>
        <collision name='collision_caster'>
          <geometry>
            <sphere>
              <radius>0.05</radius>
            </sphere>
          </geometry>
        </collision>
      </link>

      <link name="camera_link">
        <pose>0.15 0 0.2 0 0 0</pose>
        <inertial>
          <mass>0.1</mass>
          <inertia>
            <ixx>0.000166667</ixx>
            <iyy>0.000166667</iyy>
            <izz>0.000166667</izz>
          </inertia>
        </inertial>
        <collision name="collision">
          <geometry>
            <box>
              <size>0.05 0.05 0.05</size>
            </box>
          </geometry>
        </collision>
        <visual name="visual">
          <geometry>
            <box>
              <size>0.05 0.05 0.05</size>
            </box>
          </geometry>
          <material>
            <ambient>0 0 0 1</ambient>
            <diffuse>0 0 0 1</diffuse>
            <specular>0 0 0 1</specular>
          </material>
        </visual>
        <sensor name="camera" type="camera">
          <camera>
            <horizontal_fov>1.047</horizontal_fov>
            <image>
              <width>320</width>
              <height>240</height>
            </image>
            <clip>
              <near>0.1</near>
              <far>100</far>
            </clip>
          </camera>
          <always_on>1</always_on>
          <update_rate>30</update_rate>
          <visualize>true</visualize>
          <topic>camera</topic>
        </sensor>
      </link>

      <joint name='camera_joint' type='fixed'>
        <parent>chassis</parent>
        <child>camera_link</child>
      </joint>

      <link name="lidar_link">
        <pose>0 0 0.25 0 0 0</pose> 
        <inertial>
          <mass>0.1</mass>
          <inertia>
            <ixx>0.000166667</ixx>
            <iyy>0.000166667</iyy>
            <izz>0.000166667</izz>
          </inertia>
        </inertial>
        <collision name="collision">
          <geometry>
            <box>
              <size>0.1 0.1 0.1</size>
            </box>
          </geometry>
        </collision>
        <visual name="visual">
          <geometry>
            <box>
              <size>0.1 0.1 0.1</size>
            </box>
          </geometry>
        </visual>
        <sensor name='gpu_lidar' type='gpu_lidar'>
          <pose>0 0 0 0 0 0</pose>
          <topic>scan</topic>
          <ignition_frame_id>diff_drive/lidar_link</ignition_frame_id>
          <update_rate>10</update_rate>
          <lidar>
            <scan>
              <horizontal>
                <samples>800</samples>
                <resolution>1</resolution>
                <min_angle>-3.1415926536</min_angle>
                <max_angle>+3.1415926536</max_angle>
              </horizontal>
              <vertical>
                <samples>1</samples>
                <resolution>1</resolution>
                <min_angle>0.0</min_angle>
                <max_angle>0.0</max_angle>
              </vertical>
            </scan>
            <range>
              <min>0.08</min>
              <max>12.0</max>
              <resolution>0.01</resolution>
            </range>
            <noise>
              <type>gaussian</type>
              <mean>0.0</mean>
              <stddev>0.01</stddev>
            </noise>
          </lidar>
          <visualize>true</visualize>
        </sensor>
      </link>

      <joint name='lidar_joint' type='fixed'>
        <parent>chassis</parent>
        <child>lidar_link</child>
      </joint>

      <joint name='left_wheel_joint' type='revolute'>
        <parent>chassis</parent>
        <child>left_wheel</child>
        <axis>
          <xyz>0 0 1</xyz>
          <limit>
            <lower>-1.79769e+308</lower>
            <upper>1.79769e+308</upper>
          </limit>
        </axis>
      </joint>

      <joint name='right_wheel_joint' type='revolute'>
        <parent>chassis</parent>
        <child>right_wheel</child>
        <axis>
          <xyz>0 0 1</xyz>
          <limit>
            <lower>-1.79769e+308</lower>
            <upper>1.79769e+308</upper>
          </limit>
        </axis>
      </joint>

      <joint name='caster_wheel' type='ball'>
        <parent>chassis</parent>
        <child>caster</child>
      </joint>

      <plugin
        filename="ignition-gazebo-diff-drive-system"
        name="ignition::gazebo::systems::DiffDrive">
        <left_joint>left_wheel_joint</left_joint>
        <right_joint>right_wheel_joint</right_joint>
        <wheel_separation>0.3</wheel_separation>
        <wheel_radius>0.05</wheel_radius>
        <odom_publish_frequency>1</odom_publish_frequency>
        <max_linear_acceleration>1</max_linear_acceleration>
        <min_linear_acceleration>-1</min_linear_acceleration>
        <max_angular_acceleration>2</max_angular_acceleration>
        <min_angular_acceleration>-2</min_angular_acceleration>
        <max_linear_velocity>0.5</max_linear_velocity>
        <min_linear_velocity>-0.5</min_linear_velocity>
        <max_angular_velocity>1</max_angular_velocity>
        <min_angular_velocity>-1</min_angular_velocity>
      </plugin>
    </model>
</sdf>
